@generated
{
  "kind": "issue",
  "data": {
    "callable": "remote_code_execution.rce_problem",
    "callable_line": 9,
    "code": 5001,
    "line": 11,
    "start": 9,
    "end": 10,
    "filename": "remote_code_execution.py",
    "message":
      "Possible remote code execution due to [UserControlled] data reaching [RemoteCodeExecution] sink(s)",
    "traces": [
      {
        "name": "forward",
        "roots": [
          {
            "kinds": [
              {
                "leaves": [ { "name": "_user_controlled" } ],
                "kind": "UserControlled"
              }
            ],
            "root": {
              "filename": "remote_code_execution.py",
              "line": 10,
              "start": 8,
              "end": 26
            }
          }
        ]
      },
      {
        "name": "backward",
        "roots": [
          {
            "kinds": [
              {
                "leaves": [ { "name": "eval" } ],
                "kind": "RemoteCodeExecution"
              }
            ],
            "root": {
              "filename": "remote_code_execution.py",
              "line": 11,
              "start": 9,
              "end": 10
            }
          }
        ]
      }
    ],
    "features": [],
    "master_handles": [
      "remote_code_execution.rce_problem:5001:0:Call|eval|0|formal(arg):ed84aec82b00e80f14a8f4828907cb17"
    ]
  }
}
