@generated
{
  "kind": "issue",
  "data": {
    "callable": "remote_code_execution.rce_problem",
    "callable_line": 9,
    "code": 5001,
    "line": 11,
    "start": 9,
    "end": 10,
    "filename": "remote_code_execution.py",
    "message":
      "Possible remote code execution due to [UserControlled] data reaching [RemoteCodeExecution] sink(s)",
    "traces": [
      {
        "name": "forward",
        "roots": [
          {
            "root": {
              "filename": "remote_code_execution.py",
              "line": 10,
              "start": 8,
              "end": 26
            },
            "leaves": [
              { "kind": "UserControlled", "name": "_user_controlled" }
            ]
          }
        ]
      },
      {
        "name": "backward",
        "roots": [
          {
            "root": {
              "filename": "remote_code_execution.py",
              "line": 11,
              "start": 9,
              "end": 10
            },
            "leaves": [ { "kind": "RemoteCodeExecution", "name": "eval" } ]
          }
        ]
      }
    ],
    "features": []
  }
}
